<?xml version="1.0"?>
<robot name="biped" xmlns:xacro="http://www.ros.org/wiki/xacro">
    <material name="red">
        <color rgba="0.8 0 0 1"/>
    </material>

    <material name="green">
        <color rgba="0 0.8 0 1"/>
    </material>

    <material name="blue">
        <color rgba="0 0 0.8 1"/>
    </material>

    <material name="white">
        <color rgba="1 1 1 1" />
    </material>

    <material name="black">
        <color rgba="0 0 0 1" />
    </material>

    <xacro:macro name="empty_inertial" params="">
        <inertial>
            <mass value="0.0001" />
            <inertia
                    ixx="0.0001" ixy="0.0" ixz="0.0"
                    iyy="0.0001" iyz="0.0"
                    izz="0.0001" />
        </inertial>
    </xacro:macro>

    <xacro:macro name="empty_gazebo_link" params="">
        <visual>
            <geometry>
                <sphere radius="0.01"/>
            </geometry>
            <material name="red" />
        </visual>
        <xacro:empty_inertial />
    </xacro:macro>

    <xacro:macro name="cylinder_inertial" params="r l m">
        <inertial>
            <mass value="${m}" />
            <inertia
                    ixx="${(1.0/12.0)*m*(3.0*r*r + l*l)}" ixy="0.0" ixz="0.0"
                    iyy="${(1.0/12.0)*m*(3.0*r*r + l*l)}" iyz="0.0"
                    izz="${(1.0/2.0)*m*r*r}" />
        </inertial>
    </xacro:macro>

    <xacro:macro name="box_inertial" params="w h d m">
        <inertial>
            <mass value="${m}" />
            <inertia
                    ixx="${(1.0/12.0)*m*(h*h + d*d)}" ixy="0.0" ixz="0.0"
                    iyy="${(1.0/12.0)*m*(w*w + d*d)}" iyz="0.0"
                    izz="${(1.0/12.0)*m*(w*w + h*h)}" />
        </inertial>
    </xacro:macro>

    <link name="base_link">
    </link>

    <link name="waist_link">
        <xacro:empty_gazebo_link />
    </link>

    <joint name="base_fixed" type="fixed">
        <parent link="base_link" />
        <child link="waist_link" />
        <origin xyz="0 0 1.0" />
    </joint>

    <xacro:macro name="revolute_transmission" params="joint_name reduction">
        <transmission name="${joint_name}_transmission">
            <type>transmission_interface/SimpleTransmission</type>
            <actuator name="${joint_name}_motor">
                <mechanicalReduction>${reduction}</mechanicalReduction>
            </actuator>
            <joint name="${joint_name}">
                <hardwareInterface>hardware_interface/EffortJointInterface</hardwareInterface>
            </joint>
        </transmission>
    </xacro:macro>


    <xacro:macro name="biped_leg" params="parent_link prefix reflect">
        <link name="${prefix}_pelvis_yaw_link">
            <xacro:empty_gazebo_link />
        </link>

        <link name="${prefix}_pelvis_roll_link">
            <xacro:empty_gazebo_link />
        </link>

        <link name="${prefix}_pelvis_pitch_link">
            <visual>
                <origin xyz="0 0 -0.25"/>
                <material name="blue"/>
                <geometry>
                    <cylinder radius="0.02" length="0.5" />
                </geometry>
            </visual>
            <collision>
                <origin xyz="0 0 -0.25"/>
                <geometry>
                    <cylinder radius="0.02" length="0.5"/>
                </geometry>
            </collision>
            <xacro:cylinder_inertial r="0.02" l="0.5" m="0.25"/>
        </link>

        <joint name="${prefix}_pelvis_yaw" type="revolute">
            <parent link="${parent_link}" />
            <child link="${prefix}_pelvis_yaw_link" />
            <axis xyz="0 0 1" />
            <origin xyz="0 ${reflect*0.25} 0" rpy="0 0 0" />
            <limit effort="10.0" lower="-${pi/3}" upper="${pi/3}" velocity="5.0" />
        </joint>


        <joint name="${prefix}_pelvis_roll" type="revolute">
            <parent link="${prefix}_pelvis_yaw_link" />
            <child link="${prefix}_pelvis_roll_link" />
            <axis xyz="1 0 0" />
            <origin xyz="0 0 0" rpy="0 0 0" />
            <limit effort="10.0" lower="-${pi/3}" upper="${pi/3}" velocity="5.0" />
        </joint>

        <joint name="${prefix}_pelvis_pitch" type="revolute">
            <parent link="${prefix}_pelvis_roll_link" />
            <child link="${prefix}_pelvis_pitch_link" />
            <axis xyz="0 1 0" />
            <origin xyz="0 0 0" rpy="0 0 0" />
            <limit effort="10.0" lower="-${pi/3}" upper="${pi/3}" velocity="5.0" />
        </joint>

        <link name="${prefix}_knee_pitch_link">
            <visual>
                <origin xyz="0 0 -0.25"/>
                <geometry>
                    <cylinder radius="0.02" length="0.5" />
                </geometry>
                <material name="red"/>
            </visual>
            <collision>
                <origin xyz="0 0 -0.25"/>
                <geometry>
                    <cylinder radius="0.02" length="0.5" />
                </geometry>
            </collision>
            <xacro:cylinder_inertial r="0.02" l="0.5" m="0.25"/>
        </link>

        <joint name="${prefix}_knee_pitch" type="revolute">
            <parent link="${prefix}_pelvis_pitch_link" />
            <child link="${prefix}_knee_pitch_link" />
            <axis xyz="0 1 0" />
            <origin xyz="0 0 -0.5" rpy="0 0 0" />
            <limit effort="10.0" lower="0" upper="${pi/2}" velocity="5.0" />
        </joint>

        <link name="${prefix}_ankle_pitch_link">
            <xacro:empty_gazebo_link />
        </link>

        <link name="${prefix}_ankle_roll_link">
            <visual>
                <origin xyz="0.075 0 -0.02"/>
                <geometry>
                    <box size="0.3 0.1 0.02" />
                </geometry>
                <material name="green" />
            </visual>
            <collision>
                <origin xyz="0.075 0 -0.02"/>
                <geometry>
                    <box size="0.3 0.1 0.02" />
                </geometry>
            </collision>
            <xacro:box_inertial w="0.3" h="0.1" d="0.02" m="0.1"/>
        </link>

        <joint name="${prefix}_ankle_pitch" type="revolute">
            <parent link="${prefix}_knee_pitch_link" />
            <child link="${prefix}_ankle_pitch_link" />
            <axis xyz="0 1 0" />
            <origin xyz="0 0 -0.5" rpy="0 0 0" />
            <limit effort="10.0" lower="-${pi/3}" upper="${pi/3}" velocity="5.0" />
        </joint>

        <joint name="${prefix}_ankle_roll" type="revolute">
            <parent link="${prefix}_ankle_pitch_link" />
            <child link="${prefix}_ankle_roll_link" />
            <axis xyz="1 0 0" />
            <origin xyz="0 0 0" rpy="0 0 0" />
            <limit effort="10.0" lower="-${pi/3}" upper="${pi/3}" velocity="5.0" />
        </joint>

        <link name="${prefix}_ankle">
            <xacro:empty_gazebo_link />
        </link>

        <joint name="${prefix}_ankle_fixed" type="fixed">
            <parent link="${prefix}_ankle_roll_link" />
            <child link="${prefix}_ankle" />
        </joint>

        <xacro:revolute_transmission joint_name="${prefix}_pelvis_yaw" reduction="1" />
        <xacro:revolute_transmission joint_name="${prefix}_pelvis_roll" reduction="1" />
        <xacro:revolute_transmission joint_name="${prefix}_pelvis_pitch" reduction="1" />
        <xacro:revolute_transmission joint_name="${prefix}_knee_pitch" reduction="1" />
        <xacro:revolute_transmission joint_name="${prefix}_ankle_pitch" reduction="1" />
        <xacro:revolute_transmission joint_name="${prefix}_ankle_roll" reduction="1" />
    </xacro:macro>

    <xacro:macro name="biped_left_leg" params="parent_link">
        <xacro:biped_leg prefix="l" parent_link="${parent_link}" reflect="1" />
    </xacro:macro>

    <xacro:macro name="biped_right_leg" params="parent_link">
        <xacro:biped_leg prefix="r" parent_link="${parent_link}" reflect="-1" />
    </xacro:macro>

    <xacro:biped_left_leg parent_link="waist_link" />
    <xacro:biped_right_leg parent_link="waist_link" />

    <gazebo>
        <plugin name="gazebo_ros_control" filename="libgazebo_ros_control.so">
            <robotNamespace>/biped</robotNamespace>
            <robotSimType>gazebo_ros_control/DefaultRobotHWSim</robotSimType>
        </plugin>
    </gazebo>
</robot>