<?xml version="1.0"?>
<robot name="biped" xmlns:xacro="http://www.ros.org/wiki/xacro">
    <material name="red">
        <color rgba="0.8 0 0 1"/>
    </material>

    <material name="green">
        <color rgba="0 0.8 0 1"/>
    </material>

    <material name="blue">
        <color rgba="0 0 0.8 1"/>
    </material>

    <material name="white">
        <color rgba="1 1 1 1" />
    </material>

    <material name="black">
        <color rgba="0 0 0 1" />
    </material>

    <xacro:macro name="empty_inertial" params="">
        <inertial>
            <mass value="0.0001" />
            <inertia
                    ixx="0.0001" ixy="0.0" ixz="0.0"
                    iyy="0.0001" iyz="0.0"
                    izz="0.0001" />
        </inertial>
    </xacro:macro>

    <xacro:macro name="empty_gazebo_link" params="">
        <visual>
            <geometry>
                <sphere radius="0.01"/>
            </geometry>
            <material name="red" />
        </visual>
        <xacro:empty_inertial />
    </xacro:macro>

    <xacro:macro name="cylinder_inertial" params="r l m">
        <inertial>
            <mass value="${m}" />
            <inertia
                    ixx="${(1.0/12.0)*m*(3.0*r*r + l*l)}" ixy="0.0" ixz="0.0"
                    iyy="${(1.0/12.0)*m*(3.0*r*r + l*l)}" iyz="0.0"
                    izz="${(1.0/2.0)*m*r*r}" />
        </inertial>
    </xacro:macro>

    <xacro:macro name="box_inertial" params="w h d m">
        <inertial>
            <mass value="${m}" />
            <inertia
                    ixx="${(1.0/12.0)*m*(h*h + d*d)}" ixy="0.0" ixz="0.0"
                    iyy="${(1.0/12.0)*m*(w*w + d*d)}" iyz="0.0"
                    izz="${(1.0/12.0)*m*(w*w + h*h)}" />
        </inertial>
    </xacro:macro>

    <link name="base_link" />

    <link name="torso_link">
         <visual>
            <origin xyz="0 0 0" rpy="0 0 0" />
            <geometry>
                <box size="0.1 0.7 0.7"/>
            </geometry>
            <material name="red" />
        </visual>
        <collision>
            <origin xyz="0 0 0" rpy="0 0 0" />
            <geometry>
                <box size="0.1 0.7 0.7"/>
            </geometry>
        </collision>
        <xacro:box_inertial w="0.1" h="0.7" d="0.7" m="2.0" />
    </link>

    <joint name="torso_fixed" type="fixed">
        <origin xyz="0 0 0.35" rpy="0 0 0" />
        <parent link="base_link"/>
        <child link="torso_link" />
    </joint>

    <link name="imu_link">
        <xacro:empty_gazebo_link />
    </link>

    <joint name="imu_fixed" type="fixed">
        <origin xyz="0 0 0" rpy="0 0 0" />
        <parent link="torso_link" />
        <child link="imu_link" />
    </joint>

    <xacro:macro name="revolute_transmission" params="joint_name reduction">
        <transmission name="${joint_name}_transmission">
            <type>transmission_interface/SimpleTransmission</type>
            <actuator name="${joint_name}_motor">
                <mechanicalReduction>${reduction}</mechanicalReduction>
            </actuator>
            <joint name="${joint_name}">
                <hardwareInterface>hardware_interface/EffortJointInterface</hardwareInterface>
            </joint>
        </transmission>
    </xacro:macro>


    <xacro:macro name="biped_leg" params="parent_link prefix reflect">
        <link name="${prefix}_pelvis_yaw_link">
            <xacro:empty_gazebo_link />
        </link>

        <link name="${prefix}_pelvis_roll_link">
            <xacro:empty_gazebo_link />
        </link>

        <link name="${prefix}_pelvis_pitch_link">
            <visual>
                <origin xyz="0 0 -0.25"/>
                <material name="blue"/>
                <geometry>
                    <cylinder radius="0.02" length="0.5" />
                </geometry>
            </visual>
            <collision>
                <origin xyz="0 0 -0.25"/>
                <geometry>
                    <cylinder radius="0.02" length="0.5"/>
                </geometry>
            </collision>
            <xacro:cylinder_inertial r="0.02" l="0.5" m="0.25"/>
        </link>

        <joint name="${prefix}_pelvis_yaw" type="revolute">
            <parent link="${parent_link}" />
            <child link="${prefix}_pelvis_yaw_link" />
            <axis xyz="0 0 1" />
            <origin xyz="0 ${reflect*0.25} 0" rpy="0 0 0" />
            <limit effort="10.0" lower="-${pi/3}" upper="${pi/3}" velocity="5.0" />
        </joint>


        <joint name="${prefix}_pelvis_roll" type="revolute">
            <parent link="${prefix}_pelvis_yaw_link" />
            <child link="${prefix}_pelvis_roll_link" />
            <axis xyz="1 0 0" />
            <origin xyz="0 0 0" rpy="0 0 0" />
            <limit effort="10.0" lower="-${pi/3}" upper="${pi/3}" velocity="5.0" />
        </joint>

        <joint name="${prefix}_pelvis_pitch" type="revolute">
            <parent link="${prefix}_pelvis_roll_link" />
            <child link="${prefix}_pelvis_pitch_link" />
            <axis xyz="0 1 0" />
            <origin xyz="0 0 0" rpy="0 0 0" />
            <limit effort="10.0" lower="-${pi/3}" upper="${pi/3}" velocity="5.0" />
        </joint>

        <link name="${prefix}_knee_pitch_link">
            <visual>
                <origin xyz="0 0 -0.25"/>
                <geometry>
                    <cylinder radius="0.02" length="0.5" />
                </geometry>
                <material name="red"/>
            </visual>
            <collision>
                <origin xyz="0 0 -0.25"/>
                <geometry>
                    <cylinder radius="0.02" length="0.5" />
                </geometry>
            </collision>
            <xacro:cylinder_inertial r="0.02" l="0.5" m="0.25"/>
        </link>

        <joint name="${prefix}_knee_pitch" type="revolute">
            <parent link="${prefix}_pelvis_pitch_link" />
            <child link="${prefix}_knee_pitch_link" />
            <axis xyz="0 1 0" />
            <origin xyz="0 0 -0.5" rpy="0 0 0" />
            <limit effort="10.0" lower="0" upper="${pi/2}" velocity="5.0" />
        </joint>

        <link name="${prefix}_ankle_pitch_link">
            <xacro:empty_gazebo_link />
        </link>

        <link name="${prefix}_ankle_roll_link">
            <visual>
                <origin xyz="0.075 0 -0.02"/>
                <geometry>
                    <box size="0.3 0.1 0.02" />
                </geometry>
                <material name="green" />
            </visual>
            <collision>
                <origin xyz="0.075 0 -0.02"/>
                <geometry>
                    <box size="0.3 0.1 0.02" />
                </geometry>
            </collision>
            <xacro:box_inertial w="0.3" h="0.1" d="0.02" m="0.1"/>
        </link>

        <joint name="${prefix}_ankle_pitch" type="revolute">
            <parent link="${prefix}_knee_pitch_link" />
            <child link="${prefix}_ankle_pitch_link" />
            <axis xyz="0 1 0" />
            <origin xyz="0 0 -0.5" rpy="0 0 0" />
            <limit effort="10.0" lower="-${pi/3}" upper="${pi/3}" velocity="5.0" />
        </joint>

        <joint name="${prefix}_ankle_roll" type="revolute">
            <parent link="${prefix}_ankle_pitch_link" />
            <child link="${prefix}_ankle_roll_link" />
            <axis xyz="1 0 0" />
            <origin xyz="0 0 0" rpy="0 0 0" />
            <limit effort="10.0" lower="-${pi/3}" upper="${pi/3}" velocity="5.0" />
        </joint>

        <link name="${prefix}_ankle">
            <xacro:empty_gazebo_link />
        </link>

        <joint name="${prefix}_ankle_fixed" type="fixed">
            <parent link="${prefix}_ankle_roll_link" />
            <child link="${prefix}_ankle" />
        </joint>

        <xacro:revolute_transmission joint_name="${prefix}_pelvis_yaw" reduction="1" />
        <xacro:revolute_transmission joint_name="${prefix}_pelvis_roll" reduction="1" />
        <xacro:revolute_transmission joint_name="${prefix}_pelvis_pitch" reduction="1" />
        <xacro:revolute_transmission joint_name="${prefix}_knee_pitch" reduction="1" />
        <xacro:revolute_transmission joint_name="${prefix}_ankle_pitch" reduction="1" />
        <xacro:revolute_transmission joint_name="${prefix}_ankle_roll" reduction="1" />
    </xacro:macro>

    <xacro:macro name="biped_left_leg" params="parent_link">
        <xacro:biped_leg prefix="l" parent_link="${parent_link}" reflect="1" />
    </xacro:macro>

    <xacro:macro name="biped_right_leg" params="parent_link">
        <xacro:biped_leg prefix="r" parent_link="${parent_link}" reflect="-1" />
    </xacro:macro>

    <xacro:biped_left_leg parent_link="base_link" />
    <xacro:biped_right_leg parent_link="base_link" />

    <gazebo>
        <plugin name="gazebo_ros_control" filename="libgazebo_ros_control.so">
            <robotNamespace>/biped</robotNamespace>
            <robotSimType>gazebo_ros_control/DefaultRobotHWSim</robotSimType>
        </plugin>
    </gazebo>

    <gazebo reference="l_ankle_roll_link">
        <material>Gazebo/FlatBlack</material>
        <kp>1000000.0</kp>
        <kd>100.0</kd>
        <mu1>1.0</mu1>
        <mu2>1.0</mu2>
        <fdir1>1 0 0</fdir1>
        <maxVel>1.0</maxVel>
        <minDepth>0.0</minDepth>
    </gazebo>
    <gazebo reference="r_ankle_roll_link">
        <material>Gazebo/FlatBlack</material>
        <kp>1000000.0</kp>
        <kd>100.0</kd>
        <mu1>1.0</mu1>
        <mu2>1.0</mu2>
        <fdir1>1 0 0</fdir1>
        <maxVel>1.0</maxVel>
        <minDepth>0.0</minDepth>
    </gazebo>

    <gazebo reference="r_ankle_roll">
        <provideFeedback>true</provideFeedback>
    </gazebo>

    <gazebo reference="l_ankle_roll">
        <provideFeedback>true</provideFeedback>
    </gazebo>

    <gazebo>
        <plugin filename="libgazebo_ros_ft_sensor.so" name="r_ft_sensor">
            <robotNamespace>/biped</robotNamespace>
            <updateRate>100.0</updateRate>
            <topicName>r_ankle_ft_sensor</topicName>
            <jointName>r_ankle_roll</jointName>
            <noise>
                <type>gaussian</type>
                <mean>0.0</mean>
                <stddev>0.0</stddev>
            </noise>
        </plugin>
        <plugin filename="libgazebo_ros_ft_sensor.so" name="l_ft_sensor">
            <robotNamespace>/biped</robotNamespace>
            <updateRate>100.0</updateRate>
            <topicName>l_ankle_ft_sensor</topicName>
            <jointName>l_ankle_roll</jointName>
            <noise>
                <type>gaussian</type>
                <mean>0.0</mean>
                <stddev>0.0</stddev>
            </noise>
        </plugin>
    </gazebo>

    <gazebo reference="imu_link">
        <gravity>true</gravity>
        <sensor name="imu_sensor" type="imu">
            <always_on>true</always_on>
            <update_rate>100</update_rate>
            <visualize>true</visualize>
            <topic>__default_topic__</topic>
            <plugin filename="libgazebo_ros_imu_sensor.so" name="imu_plugin">
                <robotNamespace>/biped</robotNamespace>
                <topicName>imu</topicName>
                <bodyName>imu_link</bodyName>
                <updateRateHZ>10</updateRateHZ>
                <gaussianNoise>0.0</gaussianNoise>
                <xyzOffset>0 0 0</xyzOffset>
                <rpyOffset>0 0 0</rpyOffset>
                <frameName>imu_link</frameName>
            </plugin>
            <pose>0 0 0 0 0 0</pose>
        </sensor>
    </gazebo>
</robot>